[6 错误处理](#6)
[6.1 浏览器对象](#6.1)
[6.2 错误传播](#6.2)
[6.3 异步错误处理](#6.3)


## 6 错误处理
<h3 id="6.1">6.1 错误处理</h3>
```
var r1, r2, s = null;
try {
    r1 = s.length; // 此处应产生错误
    r2 = 100; // 该语句不会执行
} catch (e) {
    console.log('出错了：' + e);
} finally {
    console.log('finally');
}
console.log('r1 = ' + r1); // r1应为undefined
console.log('r2 = ' + r2); // r2应为undefined

```
```
完整的try ... catch ... finally：

try {
    ...
} catch (e) {
    ...
} finally {
    ...
}
只有try ... catch，没有finally：

try {
    ...
} catch (e) {
    ...
}
只有try ... finally，没有catch：

try {
    ...
} finally {
    ...
}
```
```
Error对象 ->
    TypeError
    ReferenceError
    ...

try {
    ...
} catch (e) {
    if (e instanceof TypeError) {
        alert('Type error!');
    } else if (e instanceof Error) {
        alert(e.message);
    } else {
        alert('Error: ' + e);
    }
}
```
```
抛出错误
var r, n, s;
try {
    s = prompt('请输入一个数字');
    n = parseInt(s);
    if (isNaN(n)) {
        throw new Error('输入错误');
    }
    // 计算平方:
    r = n * n;
    console.log(n + ' * ' + n + ' = ' + r);
} catch (e) {
    console.log('出错了：' + e);
}
```
<h3 id="6.2">6.2 错误传播</h3>
```
我们不必在每一个函数内部捕获错误，只需要在合适的地方来个统一捕获，一网打尽：
function main(s) {
    console.log('BEGIN main()');
    try {
        foo(s);
    } catch (e) {
        console.log('出错了：' + e);
    }
    console.log('END main()');
}

function foo(s) {
    console.log('BEGIN foo()');
    bar(s);
    console.log('END foo()');
}

function bar(s) {
    console.log('BEGIN bar()');
    console.log('length = ' + s.length);
    console.log('END bar()');
}

main(null);

>>>
BEGIN main()
BEGIN foo()
BEGIN bar()
出错了：TypeError: Cannot read property 'length' of null
END main()
```
<h3 id="6.3">6.3 异步错误处理</h3>
```
try在执行的时候会统一捕获，异步事件的外层函数则无法捕获其出错。
```













